Workbook

Sheet Sources & Methods
A1: Variable | B1: Code | C1: Description | D1: Source
A2: Puerto Rico Unemployment Rate | B2: UR | C2: Index Dec 2006=100, Monthly, Seasonally Adjusted | D2: https://fred.stlouisfed.org/series/PRUR#
A3: Puerto Rico Headline Consumer Price Index | B3: CCPI & HCPI | C3: Index Dec 2006=100, Monthly | D3: https://www.mercadolaboral.pr.gov/Tablas_Estadisticas/Otras_Tablas/T_Indice_Precio.aspx
A4: Proxy Funds Rate | B4: PFR | C4: Monthly Percent | D4: https://www.frbsf.org/research-and-insights/data-and-indicators/proxy-funds-rate/
A5: Proxy Funds Rate | B5: PFR_2 | C5: Index Dec 2006=100, Monthly
A6: Monetary Policy Surprise | B6: MPS | C6: Raw, unadjusted monetary policy surprise (MPS) measure from Bauer and Swanson (2023), computed as the first principal component of the changes in ED1-ED4, scaled so that the impact on ED4 is unity. | D6: https://www.frbsf.org/research-and-insights/data-and-indicators/monetary-policy-surprises/
A7: Monetary Policy Surprise | B7: MPS_2 | C7: Index Dec 2006=100, Monthly
A8: US Unemployment Rate | B8: UNRATE | C8: Index Dec 2006=100, Monthly, Seasonally Adjusted | D8: https://fred.stlouisfed.org/series/UNRATE#
A9: US Headline CPI | B9: HCPI_US | C9: Consumer Price Index for All Urban Consumers: All Items in U.S. City Average, Index Dec 2006=100, Monthly, Seasonally Adjusted | D9: https://fred.stlouisfed.org/series/CPIAUCSL#
A10: US Median Core CPI | B10: CCPI_US | C10: Median Consumer Price Index, Index Dec 2006=100, Monthly, Seasonally Adjusted | D10: https://fred.stlouisfed.org/series/MEDCPIM158SFRBCLE#
A11: Spot Crude Oil Price: West Texas Intermediate (WTI) | B11: WTI | C11: Index Dec 2006=100, Monthly, Not Seasonally Adjusted | D11: https://fred.stlouisfed.org/series/WTISPLC#
A12: Coincident Economic Activity Index for the United States | B12: EAI_US | C12: Index Dec 2006=100, Monthly, Seasonally Adjusted | D12: https://fred.stlouisfed.org/series/USPHCI#
A13: Puerto Rico Economic Activity Index | B13: EAI_PR | C13: Index Dec 2006=100, Monthly, Seasonally Adjusted | D13: https://www.desarrollo.pr.gov/en/estadisticas-economicas

Sheet Prem-Monthly-Data
A1: Date | B1: UR | C1: CCPI | D1: PFR | E1: PFR_2 | F1: HCPI | G1: MPS | H1: MPS_2 | I1: UNRATE | J1: HCPI_US | K1: CCPI_US | L1: WTI | M1: EAI_US | N1: EAI_PR
A2: 30682 | B2: 212.7451 | C2: 58.9445 | D2: 9.6279459 | E2: =(D2 / $D$277) * 100 -> 185.44427 | F2: 62.971 | H2: =(G2 / G$277) * 100 -> 0 | I2: 181.81818 | J2: 50.2708 | K2: 178.03734 | L2: 47.86394 | M2: 49.96962 | N2: 58.797016
A3: 30713 | B3: 208.82353 | C3: 59.014 | D3: 9.5495241 | E3: =(D3 / $D$277) * 100 -> 183.93378 | F3: 62.877 | H3: =(G3 / G$277) * 100 -> 0 | I3: 177.27273 | J3: 50.51699 | K3: 169.96141 | L3: 48.59745 | M3: 50.27339 | N3: 59.10174
A4: 30742 | B4: 205.88235 | C4: 59.1025 | D4: 9.7558975 | E4: =(D4 / $D$277) * 100 -> 187.90875 | F4: 63.015 | H4: =(G4 / G$277) * 100 -> 0 | I4: 177.27273 | J4: 50.6647 | K4: 143.94273 | L4: 49.59052 | M4: 50.50628 | N4: 59.369979
A5: 30773 | B5: 203.92157 | C5: 59.1505 | D5: 10.155588 | E5: =(D5 / $D$277) * 100 -> 195.60721 | F5: 63.194 | H5: =(G5 / G$277) * 100 -> 0 | I5: 175 | J5: 50.86164 | K5: 164.14153 | L5: 49.35999 | M5: 50.75942 | N5: 59.741569
A6: 30803 | B6: 201.96078 | C6: 59.2485 | D6: 10.460964 | E6: =(D6 / $D$277) * 100 -> 201.48907 | F6: 63.303 | H6: =(G6 / G$277) * 100 -> 0 | I6: 168.18182 | J6: 50.96012 | K6: 124.65407 | L6: 49.202 | M6: 51.04293 | N6: 60.15355
A7: 30834 | B7: 201.96078 | C7: 59.2835 | D7: 11.350893 | E7: =(D7 / $D$277) * 100 -> 218.63002 | F7: 63.397 | H7: =(G7 / G$277) * 100 -> 0 | I7: 163.63636 | J7: 51.05859 | K7: 166.58958 | L7: 48.31049 | M7: 51.31632 | N7: 60.140189
A8: 30864 | B8: 200.98039 | C8: 59.2835 | D8: 11.861948 | E8: =(D8 / $D$277) * 100 -> 228.47347 | F8: 63.77 | H8: =(G8 / G$277) * 100 -> 0 | I8: 170.45455 | J8: 51.25554 | K8: 172.79862 | L8: 46.35177 | M8: 51.46821 | N8: 60.135746
A9: 30895 | B9: 200 | C9: 59.2825 | D9: 11.992331 | E9: =(D9 / $D$277) * 100 -> 230.98479 | F9: 63.793 | H9: =(G9 / G$277) * 100 -> 0 | I9: 170.45455 | J9: 51.40325 | K9: 172.12357 | L9: 47.1546 | M9: 51.68084 | N9: 60.268702
A10: 30926 | B10: 199.01961 | C10: 59.416 | D10: 11.799317 | E10: =(D10 / $D$277) * 100 -> 227.26715 | F10: 63.641 | H10: =(G10 / G$277) * 100 -> 0 | I10: 165.90909 | J10: 51.55096 | K10: 164.2561 | L10: 47.25294 | M10: 51.92386 | N10: 60.385669
A11: 30956 | B11: 198.03922 | C11: 59.3905 | D11: 11.043598 | E11: =(D11 / $D$277) * 100 -> 212.7112 | F11: 63.467 | H11: =(G11 / G$277) * 100 -> 0 | I11: 168.18182 | J11: 51.74791 | K11: 128.28745 | L11: 46.37272 | M11: 52.09599 | N11: 60.675029
A12: 30987 | B12: 199.01961 | C12: 59.5355 | D12: 9.8914347 | E12: =(D12 / $D$277) * 100 -> 190.51934 | F12: 63.506 | H12: =(G12 / G$277) * 100 -> 0 | I12: 163.63636 | J12: 51.84638 | K12: 95.68816 | L12: 45.29744 | M12: 52.35925 | N12: 60.559392
A13: 31017 | B13: 201.96078 | C13: 59.461 | D13: 8.8665074 | E13: =(D13 / $D$277) * 100 -> 170.77817 | F13: 63.26 | H13: =(G13 / G$277) * 100 -> 0 | I13: 165.90909 | J13: 51.94485 | K13: 129.15993 | L13: 40.99468 | M13: 52.48076 | N13: 60.79249
... A50: 32143 | B50: 157.84314 | C50: 63.0205 | D50: 6.811974 | E50: =(D50 / $D$277) * 100 -> 131.20572 | F50: 65.683 | H50: =(G50 / G$277) * 100 -> 0 | I50: 129.54545 | J50: 57.11472 | K50: 121.75875 | L50: 27.66403 | M50: 59.10288 | N50: 69.60052
A51: 32174 | B51: 156.86275 | C51: 62.4 | D51: 6.3840216 | E51: =(D51 / $D$277) * 100 -> 122.96291 | F51: 65.339 | G51: 0.012022034 | H51: =(G51 / G$277) * 100 -> -46.48087 | I51: 129.54545 | J51: 57.2132 | K51: 106.72484 | L51: 27.02724 | M51: 59.36614 | N51: 69.741882
A52: 32203 | B52: 154.90196 | C52: 62.597 | D52: 6.2990889 | E52: =(D52 / $D$277) * 100 -> 121.32701 | F52: 65.501 | G52: 0.013088246 | H52: =(G52 / G$277) * 100 -> -50.603174 | I52: 129.54545 | J52: 57.36091 | K52: 162.13923 | L52: 26.1438 | M52: 59.5889 | N52: 70.279375
A53: 32234 | B53: 150.98039 | C53: 62.8605 | D53: 6.5310722 | E53: =(D53 / $D$277) * 100 -> 125.79526 | F53: 65.844 | G53: 0.061491817 | H53: =(G53 / G$277) * 100 -> -237.74622 | I53: 122.72727 | J53: 57.70556 | K53: 173.81828 | L53: 28.8167 | M53: 59.86229 | N53: 70.779584
A54: 32264 | B54: 148.03922 | C54: 62.83 | D54: 6.8635717 | E54: =(D54 / $D$277) * 100 -> 132.19954 | F54: 65.996 | G54: 0.18319334 | H54: =(G54 / G$277) * 100 -> -708.28162 | I54: 127.27273 | J54: 57.85327 | K54: 125.24428 | L54: 28.1122 | M54: 60.00405 | N54: 71.430989
A55: 32295 | B55: 146.07843 | C55: 63.014 | D55: 7.185343 | E55: =(D55 / $D$277) * 100 -> 138.39719 | F55: 66.215 | G55: 0.028787744 | H55: =(G55 / G$277) * 100 -> -111.30225 | I55: 122.72727 | J55: 58.09946 | K55: 171.45323 | L55: 26.6484 | M55: 60.29769 | N55: 71.848533
A56: 32325 | B56: 144.11765 | C56: 63.104 | D56: 7.3784162 | E56: =(D56 / $D$277) * 100 -> 142.11598 | F56: 66.402 | G56: 0.072977219 | H56: =(G56 / G$277) * 100 -> -282.15231 | I56: 122.72727 | J56: 58.34564 | K56: 167.69946 | L56: 24.98468 | M56: 60.49008 | N56: 71.989592
A57: 32356 | B57: 142.15686 | C57: 63.4475 | D57: 7.8047222 | E57: =(D57 / $D$277) * 100 -> 150.32708 | F57: 66.857 | G57: 0.19255306 | H57: =(G57 / G$277) * 100 -> -744.46919 | I57: 127.27273 | J57: 58.59183 | K57: 193.48358 | L57: 25.0266 | M57: 60.60146 | N57: 72.144239
A58: 32387 | B58: 141.17647 | C58: 63.69 | D58: 7.8608286 | E58: =(D58 / $D$277) * 100 -> 151.40775 | F58: 66.917 | G58: -0.004677435 | H58: =(G58 / G$277) * 100 -> 18.084398 | I58: 122.72727 | J58: 58.83801 | K58: 183.79367 | L58: 23.32259 | M58: 60.87485 | N58: 72.370894
A59: 32417 | B59: 141.17647 | C59: 63.735 | D59: 7.8287278 | E59: =(D59 / $D$277) * 100 -> 150.78945 | F59: 66.838 | G59: 0 | H59: =(G59 / G$277) * 100 -> 0 | I59: 122.72727 | J59: 59.03496 | K59: 156.76481 | L59: 22.24408 | M59: 61.06723 | N59: 72.838998
A60: 32448 | B60: 141.17647 | C60: 63.8015 | D60: 8.1463574 | E60: =(D60 / $D$277) * 100 -> 156.90733 | F60: 66.895 | G60: 0.096848633 | H60: =(G60 / G$277) * 100 -> -374.44651 | I60: 120.45455 | J60: 59.23191 | K60: 108.47899 | L60: 22.53265 | M60: 61.3305 | N60: 72.858637
A61: 32478 | B61: 141.17647 | C61: 64.756 | D61: 8.9101183 | E61: =(D61 / $D$277) * 100 -> 171.61816 | F61: 67.301 | G61: 0.05008562 | H61: =(G61 / G$277) * 100 -> -193.64637 | I61: 120.45455 | J61: 59.42885 | K61: 144.92799 | L61: 26.2228 | M61: 61.53301 | N61: 72.955545
A62: 32509 | B62: 141.17647 | C62: 64.7615 | D62: 9.2384922 | E62: =(D62 / $D$277) * 100 -> 177.94299 | F62: 67.649 | G62: 0.039146391 | H62: =(G62 / G$277) * 100 -> -151.35195 | I62: 122.72727 | J62: 59.67504 | K62: 171.76085 | L62: 28.99081 | M62: 61.70514 | N62: 72.948528
... A481: 45261 | B481: 55.88235 | C481: 130.705 | D481: 6.3684936 | E481: =(D481 / $D$277) * 100 -> 122.66382 | F481: 134.262 | G481: -0.081874298 | H481: =(G481 / G$277) * 100 -> 316.55114 | I481: 86.36364 | J481: 152.01428 | K481: 154.75449 | L481: 115.91166 | M481: 144.22843 | N481: 81.869996
A482: 45292 | B482: 56.86275 | C482: 129.866 | D482: 5.9006975 | E482: =(D482 / $D$277) * 100 -> 113.65358 | F482: 134.643 | H482: =(G482 / G$277) * 100 -> 0 | I482: 84.09091 | J482: 152.48548 | K482: 201.429 | L482: 119.53893 | M482: 144.54232 | N482: 82.152722
A483: 45323 | B483: 57.84314 | C483: 132.022 | D483: 6.1375511 | E483: =(D483 / $D$277) * 100 -> 118.21563 | F483: 135.185 | H483: =(G483 / G$277) * 100 -> 0 | I483: 88.63636 | J483: 153.11029 | K483: 165.83496 | L483: 124.53651 | M483: 144.76509 | N483: 82.010074
A484: 45352 | B484: 57.84314 | C484: 132.583 | D484: 6.2432227 | E484: =(D484 / $D$277) * 100 -> 120.25097 | F484: 136.136 | H484: =(G484 / G$277) * 100 -> 0 | I484: 88.63636 | J484: 153.78877 | K484: 175.38687 | L484: 131.03337 | M484: 145.14986 | N484: 82.147868
A485: 45383 | B485: 57.84314 | C485: 132.628 | D485: 6.3188847 | E485: =(D485 / $D$277) * 100 -> 121.7083 | F485: 136.398 | H485: =(G485 / G$277) * 100 -> 0 | I485: 88.63636 | J485: 154.1226 | K485: 152.00059 | L485: 137.59471 | M485: 145.43337 | N485: 81.808533
A486: 45413 | B486: 56.86275 | C486: 132.571 | D486: 6.4089732 | E486: =(D486 / $D$277) * 100 -> 123.4435 | F486: 136.5 | H486: =(G486 / G$277) * 100 -> 0 | I486: 88.63636 | J486: 154.19744 | K486: 85.44796 | L486: 129.0021 | M486: 145.77764 | N486: 81.863647
A487: 45444 | B487: 55.88235 | C487: 132.206 | D487: 6.3519158 | E487: =(D487 / $D$277) * 100 -> 122.34452 | F487: 136.275 | H487: =(G487 / G$277) * 100 -> 0 | I487: 93.18182 | J487: 154.13294 | K487: 93.98013 | L487: 128.59906 | M487: 145.9599 | N487: 81.741984
A488: 45474 | B488: 54.90196 | C488: 132.661 | D488: 5.9669591 | E488: =(D488 / $D$277) * 100 -> 114.92985 | F488: 136.898 | H488: =(G488 / G$277) * 100 -> 0 | I488: 95.45455 | J488: 154.39143 | K488: 92.66697 | L488: 131.87167 | M488: 146.22317 | N488: 81.889177
A489: 45505 | B489: 53.92157 | C489: 134.524 | D489: 5.35073 | E489: =(D489 / $D$277) * 100 -> 103.06064 | F489: 136.354 | H489: =(G489 / G$277) * 100 -> 0 | I489: 95.45455 | J489: 154.63417 | K489: 135.81651 | L489: 123.6176 | M489: 146.46618 | N489: 81.753411
A490: 45536 | B490: 52.94118 | C490: 133.672 | D490: 4.7328859 | E490: =(D490 / $D$277) * 100 -> 91.160314 | F490: 136.676 | H490: =(G490 / G$277) * 100 -> 0 | I490: 93.18182 | J490: 154.96406 | K490: 152.1332 | L490: 113.23553 | M490: 146.88133 | N490: 81.564381
A491: 45566 | B491: 52.94118 | C491: 134.158 | D491: 4.9461187 | E491: =(D491 / $D$277) * 100 -> 95.2674 | F491: 136.751 | H491: =(G491 / G$277) * 100 -> 0 | I491: 93.18182 | J491: 155.4067 | K491: 145.61825 | L491: 116.05675 | M491: 147.13447 | N491: 81.362234
A492: 45597 | B492: 52.94118 | C492: 134.143 | D492: 5.3417577 | E492: =(D492 / $D$277) * 100 -> 102.88782 | F492: 136.744 | H492: =(G492 / G$277) * 100 -> 0 | I492: 95.45455 | J492: 155.84835 | K492: 128.00538 | L492: 112.76802 | M492: 147.43823 | N492: 81.036841
A493: 45627 | B493: 52.94118 | C493: 132.7983 | D493: 5.1797695 | E493: =(D493 / $D$277) * 100 -> 99.767757 | F493: 136.8362 | H493: =(G493 / G$277) * 100 -> 0 | I493: 93.18182 | J493: 156.37814 | K493: 116.33353 | L493: 113.04208 | M493: 147.87363 | N493: 80.752432
... A502: 45901 | B502: 55.88235 | C502: 137.4094 | D502: 3.926555 | E502: =(D502 / $D$277) * 100 -> 75.629541 | F502: 139.328 | H502: =(G502 / G$277) * 100 -> 0 | I502: 100 | J502: 159.64796 | K502: 89.36696 | L502: 103.1114 | M502: 150.05063 | N502: 81.519992
...

Sheet Prem-Quarterly-Data-1984
A1: Date | B1: UR | C1: CCPI | D1: PFR_2 | E1: HCPI | F1: MPS_2 | G1: UNRATE | H1: HCPI_US | I1: CCPI_US | J1: WTI | K1: EAI_US | L1: EAI_PR
A2: 30682 | B2: {=_xlfn.BYROW(_xlfn.WRAPROWS('Prem-Monthly-Data'!$B$2:$B$505, 3), _xlfn.LAMBDA(_xlpm.row, AVERAGE(_xlpm.row)))} -> 209.15033 | C2: {=_xlfn.BYROW(_xlfn.WRAPROWS('Prem-Monthly-Data'!$C$2:$C$505, 3), _xlfn.LAMBDA(_xlpm.row, AVERAGE(_xlpm.row)))} -> 59.020333 | D2: {=_xlfn.BYROW(_xlfn.WRAPROWS('Prem-Monthly-Data'!$E$2:$E$505, 3), _xlfn.LAMBDA(_xlpm.row, AVERAGE(_xlpm.row)))} -> 185.76227 | E2: {=_xlfn.BYROW(_xlfn.WRAPROWS('Prem-Monthly-Data'!$F$2:$F$505, 3), _xlfn.LAMBDA(_xlpm.row, AVERAGE(_xlpm.row)))} -> 62.954333 | F2: {=_xlfn.BYROW(_xlfn.WRAPROWS('Prem-Monthly-Data'!$H$2:$H$505, 3), _xlfn.LAMBDA(_xlpm.row, AVERAGE(_xlpm.row)))} -> 0 | G2: {=_xlfn.BYROW(_xlfn.WRAPROWS('Prem-Monthly-Data'!$I$2:$I$505, 3), _xlfn.LAMBDA(_xlpm.row, AVERAGE(_xlpm.row)))} -> 178.78788 | H2: {=_xlfn.BYROW(_xlfn.WRAPROWS('Prem-Monthly-Data'!$J$2:$J$505, 3), _xlfn.LAMBDA(_xlpm.row, AVERAGE(_xlpm.row)))} -> 50.484163 | I2: {=_xlfn.BYROW(_xlfn.WRAPROWS('Prem-Monthly-Data'!$K$2:$K$505, 3), _xlfn.LAMBDA(_xlpm.row, AVERAGE(_xlpm.row)))} -> 163.98049 | J2: {=_xlfn.BYROW(_xlfn.WRAPROWS('Prem-Monthly-Data'!$L$2:$L$505, 3), _xlfn.LAMBDA(_xlpm.row, AVERAGE(_xlpm.row)))} -> 48.68397 | K2: {=_xlfn.BYROW(_xlfn.WRAPROWS('Prem-Monthly-Data'!$M$2:$M$505, 3), _xlfn.LAMBDA(_xlpm.row, AVERAGE(_xlpm.row)))} -> 50.249763 | L2: {=_xlfn.BYROW(_xlfn.WRAPROWS('Prem-Monthly-Data'!$N$2:$N$505, 3), _xlfn.LAMBDA(_xlpm.row, AVERAGE(_xlpm.row)))} -> 59.089578
A3: 30773 | B3: 202.61438 | C3: 59.2275 | D3: 205.2421 | E3: 63.298 | F3: 0 | G3: 168.93939 | H3: 50.960117 | I3: 151.79506 | J3: 48.957493 | K3: 51.039557 | L3: 60.011769
A4: 30864 | B4: 200 | C4: 59.327333 | D4: 228.90847 | E4: 63.734667 | F4: 0 | G4: 168.9394 | H4: 51.40325 | I4: 169.7261 | J4: 46.91977 | K4: 51.69097 | L4: 60.263372
A5: 30956 | B5: 199.6732 | C5: 59.462333 | D5: 191.33624 | E5: 63.411 | F5: 0 | G5: 165.90909 | H5: 51.84638 | I5: 117.71185 | J5: 44.221613 | K5: 52.312 | L5: 60.675637
A6: 31048 | B6: 212.7451 | C6: 59.469667 | D6: 170.04813 | E6: 63.346 | F6: 0 | G6: 164.39394 | H6: 52.322337 | I6: 163.79147 | J6: 43.60793 | K6: 52.852033 | L6: 60.896895
A7: 31138 | B7: 221.56863 | C7: 60.026667 | D7: 161.63948 | E7: 63.643667 | F7: 0 | G7: 165.90909 | H7: 52.798293 | I7: 155.78622 | J7: 44.908917 | K7: 53.36506 | L7: 60.91984
A8: 31229 | B8: 212.7451 | C8: 60.151167 | D8: 149.336 | E8: 63.518333 | F8: 0 | G8: 163.63637 | H8: 53.126537 | I8: 114.23675 | J8: 44.802513 | K8: 53.871337 | L8: 60.638404
A9: 31321 | B9: 203.26797 | C9: 60.204833 | D9: 148.42203 | E9: 63.426333 | F9: 0 | G9: 159.84849 | H9: 53.668143 | I9: 146.00207 | J9: 47.06271 | K9: 54.391117 | L9: 61.100812
A10: 31413 | B10: 197.38562 | C10: 61.472 | D10: 143.85404 | E10: 63.497 | F10: 0 | G10: 159.84848 | H10: 53.947153 | I10: 146.51911 | J10: 27.408783 | K10: 54.82314 | L10: 62.409857
A11: 31503 | B11: 190.84967 | C11: 61.749333 | D11: 140.8455 | E11: 62.972333 | F11: 0 | G11: 162.87879 | H11: 53.684553 | I11: 119.93785 | J11: 22.440757 | K11: 55.194413 | L11: 63.379546
A12: 31594 | B12: 179.08497 | C12: 60.790833 | D12: 132.41586 | E12: 63.289667 | F12: 0 | G12: 158.33333 | H12: 54.0128 | I12: 138.24644 | J12: 22.344027 | K12: 55.67369 | L12: 64.505281
A13: 31686 | B13: 174.183 | C13: 60.447167 | D13: 119.72356 | E13: 63.577667 | F13: 0 | G13: 155.30303 | H13: 54.390287 | I13: 155.36714 | J13: 24.791767 | K13: 56.210343 | L13: 65.097088
A14: 31778 | B14: 173.52941 | C14: 60.813 | D14: 116.30271 | E14: 63.839 | F14: 0 | G14: 150 | H14: 55.046773 | I14: 152.81389 | J14: 29.387393 | K14: 56.76387 | L14: 66.253115
... A169: 45931 | B169: 55.88235 | C169: 138.35865 | D169: 73.492852 | E169: 139.491 | F169: 0 | G169: 101.13636 | H169: 160.28902 | I169: 72.613123 | J169: 96.147027 | K169: 150.33752 | L169: 81.599854

Sheet Prem-Quarterly-Data-2006-2023
A1: Date | B1: UR | C1: CCPI | D1: PFR_2 | E1: HCPI | F1: MPS_2 | G1: UNRATE | H1: HCPI_US | I1: CCPI_US | J1: WTI | K1: EAI_US | L1: EAI_PR
A2: 38718 | B2: 104.57516 | C2: 96.502833 | D2: 98.104992 | E2: 95.875 | F2: -130.41741 | G2: 107.57576 | H2: 98.211063 | I2: 98.310867 | J2: 102.12263 | K2: 97.63062 | L2: 100.65462
A3: 38808 | B3: 104.90196 | C3: 96.608333 | D3: 101.0154 | E3: 98.025333 | F3: -42.913311 | G3: 105.30303 | H3: 99.097327 | I3: 126.88615 | J3: 113.70305 | K3: 98.454167 | L3: 99.960395
A4: 38899 | B4: 105.55556 | C4: 97.730833 | D4: 104.23553 | E4: 99.641667 | F4: -4.1637968 | G4: 105.30303 | H4: 100.03283 | I4: 119.62817 | J4: 113.56333 | K4: 99.092073 | L4: 99.373667
A5: 38991 | B5: 100.3268 | C5: 98.558167 | D5: 101.55265 | E5: 98.621 | F5: 35.234517 | G5: 100.75758 | H5: 99.622517 | I5: 114.97318 | J5: 96.877853 | K5: 99.750237 | L5: 99.942027
A6: 39083 | B6: 102.28758 | C6: 100.1305 | D6: 100.84962 | E6: 100.48133 | F6: 116.34126 | G6: 102.27273 | H6: 100.59921 | I6: 123.52222 | J6: 93.71272 | K6: 100.46915 | L6: 99.203518
A7: 39173 | B7: 108.82353 | C7: 100.28967 | D7: 98.795809 | E7: 101.96633 | F7: -96.207158 | G7: 102.27273 | H7: 101.73855 | I7: 97.71555 | J7: 104.73964 | K7: 101.12731 | L7: 98.274226
A8: 39264 | B8: 114.05229 | C8: 100.6195 | D8: 89.887892 | E8: 102.412 | F8: 255.38393 | G8: 106.0606 | H8: 102.38257 | I8: 106.61042 | J8: 121.7153 | K8: 101.51208 | L8: 98.386169
A9: 39356 | B9: 112.4183 | C9: 101.26283 | D9: 68.957376 | E9: 103.883 | F9: -216.44871 | G9: 109.09091 | H9: 103.63844 | I9: 120.98667 | J9: 146.46139 | K9: 101.9171 | L9: 96.862525
A10: 39448 | B10: 105.22876 | C10: 101.92233 | D10: 32.06982 | E10: 105.322 | F10: 86.844506 | G10: 113.63636 | H10: 104.76104 | I10: 112.2902 | J10: 157.91284 | K10: 102.22425 | L10: 96.278418
A11: 39539 | B11: 109.15033 | C11: 103.07283 | D11: 42.599509 | E11: 107.32133 | F11: 148.1443 | G11: 121.21212 | H11: 106.12392 | I11: 107.10371 | J11: 199.84416 | K11: 102.25462 | L11: 95.666721
A12: 39630 | B12: 119.60784 | C12: 104.11283 | D12: 44.710224 | E12: 109.83467 | F12: -108.12394 | G12: 136.36363 | H12: 107.76021 | I12: 123.56726 | J12: 190.20367 | K12: 101.96436 | L12: 94.529118
A13: 39722 | B13: 128.43137 | C13: 104.49733 | D13: 16.607421 | E13: 107.56167 | F13: 360.78328 | G13: 156.0606 | H13: 105.2923 | I13: 55.05254 | J13: 94.099627 | K13: 101.14081 | L13: 93.034293
... A73: 45200 | B73: 55.228757 | C73: 130.45917 | D73: 127.90058 | E73: 134.53267 | F73: 113.54457 | G73: 86.363637 | H73: 151.74544 | I73: 178.5295 | J73: 126.40658 | K73: 143.89766 | L73: 82.090266
